The following values were not passed to `accelerate launch` and had defaults used instead:
	`--num_processes` was set to a value of `4`
	`--num_machines` was set to a value of `1`
	`--dynamo_backend` was set to a value of `'no'`
To avoid this warning pass in values for each of the problematic parameters or run `accelerate config`.
2024-12-09 08:52:14.447250: E external/local_xla/xla/stream_executor/cuda/cuda_fft.cc:477] Unable to register cuFFT factory: Attempting to register factory for plugin cuFFT when one has already been registered
2024-12-09 08:52:14.447250: E external/local_xla/xla/stream_executor/cuda/cuda_fft.cc:477] Unable to register cuFFT factory: Attempting to register factory for plugin cuFFT when one has already been registered
2024-12-09 08:52:14.447299: E external/local_xla/xla/stream_executor/cuda/cuda_fft.cc:477] Unable to register cuFFT factory: Attempting to register factory for plugin cuFFT when one has already been registered
2024-12-09 08:52:14.447251: E external/local_xla/xla/stream_executor/cuda/cuda_fft.cc:477] Unable to register cuFFT factory: Attempting to register factory for plugin cuFFT when one has already been registered
WARNING: All log messages before absl::InitializeLog() is called are written to STDERR
WARNING: All log messages before absl::InitializeLog() is called are written to STDERR
WARNING: All log messages before absl::InitializeLog() is called are written to STDERR
E0000 00:00:1733730734.465401  888543 cuda_dnn.cc:8310] Unable to register cuDNN factory: Attempting to register factory for plugin cuDNN when one has already been registered
E0000 00:00:1733730734.465399  888545 cuda_dnn.cc:8310] Unable to register cuDNN factory: Attempting to register factory for plugin cuDNN when one has already been registered
E0000 00:00:1733730734.465399  888542 cuda_dnn.cc:8310] Unable to register cuDNN factory: Attempting to register factory for plugin cuDNN when one has already been registered
WARNING: All log messages before absl::InitializeLog() is called are written to STDERR
E0000 00:00:1733730734.465671  888544 cuda_dnn.cc:8310] Unable to register cuDNN factory: Attempting to register factory for plugin cuDNN when one has already been registered
E0000 00:00:1733730734.470775  888545 cuda_blas.cc:1418] Unable to register cuBLAS factory: Attempting to register factory for plugin cuBLAS when one has already been registered
E0000 00:00:1733730734.470778  888542 cuda_blas.cc:1418] Unable to register cuBLAS factory: Attempting to register factory for plugin cuBLAS when one has already been registered
E0000 00:00:1733730734.470793  888543 cuda_blas.cc:1418] Unable to register cuBLAS factory: Attempting to register factory for plugin cuBLAS when one has already been registered
E0000 00:00:1733730734.470916  888544 cuda_blas.cc:1418] Unable to register cuBLAS factory: Attempting to register factory for plugin cuBLAS when one has already been registered
Traceback (most recent call last):
Traceback (most recent call last):
  File "/cluster/scratch/ckeusch/dsl-as24-challenge-3/src/main.py", line 12, in <module>
  File "/cluster/scratch/ckeusch/dsl-as24-challenge-3/src/main.py", line 12, in <module>
Traceback (most recent call last):
Traceback (most recent call last):
  File "/cluster/scratch/ckeusch/dsl-as24-challenge-3/src/main.py", line 12, in <module>
  File "/cluster/scratch/ckeusch/dsl-as24-challenge-3/src/main.py", line 12, in <module>
        from train import train_modelfrom train import train_model    

from train import train_model
  File "/cluster/scratch/ckeusch/dsl-as24-challenge-3/src/train.py", line 7, in <module>
  File "/cluster/scratch/ckeusch/dsl-as24-challenge-3/src/train.py", line 7, in <module>
  File "/cluster/scratch/ckeusch/dsl-as24-challenge-3/src/train.py", line 7, in <module>
    from train import train_model
  File "/cluster/scratch/ckeusch/dsl-as24-challenge-3/src/train.py", line 7, in <module>
    from src.models.WaveDecompNet.train import fit_wave_decomp_net        
from src.models.WaveDecompNet.train import fit_wave_decomp_netfrom src.models.WaveDecompNet.train import fit_wave_decomp_net

  File "/cluster/scratch/ckeusch/dsl-as24-challenge-3/src/models/WaveDecompNet/train.py", line 8, in <module>
  File "/cluster/scratch/ckeusch/dsl-as24-challenge-3/src/models/WaveDecompNet/train.py", line 8, in <module>
  File "/cluster/scratch/ckeusch/dsl-as24-challenge-3/src/models/WaveDecompNet/train.py", line 8, in <module>
    from src.models.WaveDecompNet.train import fit_wave_decomp_net
  File "/cluster/scratch/ckeusch/dsl-as24-challenge-3/src/models/WaveDecompNet/train.py", line 8, in <module>
            from src.callbacks import GPUMonitorCallback, LogCallbackfrom src.callbacks import GPUMonitorCallback, LogCallbackfrom src.callbacks import GPUMonitorCallback, LogCallback


  File "/cluster/scratch/ckeusch/dsl-as24-challenge-3/src/callbacks.py", line 12, in <module>
  File "/cluster/scratch/ckeusch/dsl-as24-challenge-3/src/callbacks.py", line 12, in <module>
  File "/cluster/scratch/ckeusch/dsl-as24-challenge-3/src/callbacks.py", line 12, in <module>
    from src.callbacks import GPUMonitorCallback, LogCallback
  File "/cluster/scratch/ckeusch/dsl-as24-challenge-3/src/callbacks.py", line 12, in <module>
            from src.models.CleanUNet.validate import visualize_predictions_clean_unetfrom src.models.CleanUNet.validate import visualize_predictions_clean_unetfrom src.models.CleanUNet.validate import visualize_predictions_clean_unet


  File "/cluster/scratch/ckeusch/dsl-as24-challenge-3/src/models/CleanUNet/validate.py", line 18, in <module>
  File "/cluster/scratch/ckeusch/dsl-as24-challenge-3/src/models/CleanUNet/validate.py", line 18, in <module>
  File "/cluster/scratch/ckeusch/dsl-as24-challenge-3/src/models/CleanUNet/validate.py", line 18, in <module>
    from src.models.CleanUNet.validate import visualize_predictions_clean_unet
  File "/cluster/scratch/ckeusch/dsl-as24-challenge-3/src/models/CleanUNet/validate.py", line 18, in <module>
        from src.models.CleanUNet.dataset import CleanUNetDatasetfrom src.models.CleanUNet.dataset import CleanUNetDataset    

from src.models.CleanUNet.dataset import CleanUNetDataset
ModuleNotFoundError: ModuleNotFoundErrorNo module named 'src.models.CleanUNet.dataset': ModuleNotFoundError
No module named 'src.models.CleanUNet.dataset': 
No module named 'src.models.CleanUNet.dataset'
    from src.models.CleanUNet.dataset import CleanUNetDataset
ModuleNotFoundError: No module named 'src.models.CleanUNet.dataset'
[2024-12-09 08:52:23,474] torch.distributed.elastic.multiprocessing.api: [ERROR] failed (exitcode: 1) local_rank: 0 (pid: 888542) of binary: /cluster/home/ckeusch/miniconda3/envs/CDiffSD/bin/python3.11
Traceback (most recent call last):
  File "/cluster/home/ckeusch/miniconda3/envs/CDiffSD/bin/accelerate", line 10, in <module>
    sys.exit(main())
             ^^^^^^
  File "/cluster/home/ckeusch/miniconda3/envs/CDiffSD/lib/python3.11/site-packages/accelerate/commands/accelerate_cli.py", line 46, in main
    args.func(args)
  File "/cluster/home/ckeusch/miniconda3/envs/CDiffSD/lib/python3.11/site-packages/accelerate/commands/launch.py", line 1066, in launch_command
    multi_gpu_launcher(args)
  File "/cluster/home/ckeusch/miniconda3/envs/CDiffSD/lib/python3.11/site-packages/accelerate/commands/launch.py", line 711, in multi_gpu_launcher
    distrib_run.run(args)
  File "/cluster/home/ckeusch/miniconda3/envs/CDiffSD/lib/python3.11/site-packages/torch/distributed/run.py", line 803, in run
    elastic_launch(
  File "/cluster/home/ckeusch/miniconda3/envs/CDiffSD/lib/python3.11/site-packages/torch/distributed/launcher/api.py", line 135, in __call__
    return launch_agent(self._config, self._entrypoint, list(args))
           ^^^^^^^^^^^^^^^^^^^^^^^^^^^^^^^^^^^^^^^^^^^^^^^^^^^^^^^^
  File "/cluster/home/ckeusch/miniconda3/envs/CDiffSD/lib/python3.11/site-packages/torch/distributed/launcher/api.py", line 268, in launch_agent
    raise ChildFailedError(
torch.distributed.elastic.multiprocessing.errors.ChildFailedError: 
============================================================
src/main.py FAILED
------------------------------------------------------------
Failures:
[1]:
  time      : 2024-12-09_08:52:23
  host      : eu-g3-075.euler.ethz.ch
  rank      : 1 (local_rank: 1)
  exitcode  : 1 (pid: 888543)
  error_file: <N/A>
  traceback : To enable traceback see: https://pytorch.org/docs/stable/elastic/errors.html
[2]:
  time      : 2024-12-09_08:52:23
  host      : eu-g3-075.euler.ethz.ch
  rank      : 2 (local_rank: 2)
  exitcode  : 1 (pid: 888544)
  error_file: <N/A>
  traceback : To enable traceback see: https://pytorch.org/docs/stable/elastic/errors.html
[3]:
  time      : 2024-12-09_08:52:23
  host      : eu-g3-075.euler.ethz.ch
  rank      : 3 (local_rank: 3)
  exitcode  : 1 (pid: 888545)
  error_file: <N/A>
  traceback : To enable traceback see: https://pytorch.org/docs/stable/elastic/errors.html
------------------------------------------------------------
Root Cause (first observed failure):
[0]:
  time      : 2024-12-09_08:52:23
  host      : eu-g3-075.euler.ethz.ch
  rank      : 0 (local_rank: 0)
  exitcode  : 1 (pid: 888542)
  error_file: <N/A>
  traceback : To enable traceback see: https://pytorch.org/docs/stable/elastic/errors.html
============================================================
