The following values were not passed to `accelerate launch` and had defaults used instead:
	`--num_processes` was set to a value of `4`
	`--num_machines` was set to a value of `1`
	`--dynamo_backend` was set to a value of `'no'`
To avoid this warning pass in values for each of the problematic parameters or run `accelerate config`.
Traceback (most recent call last):
  File "/cluster/home/ckeusch/miniconda3/envs/CDiffSD/bin/accelerate", line 10, in <module>
    sys.exit(main())
             ^^^^^^
  File "/cluster/home/ckeusch/miniconda3/envs/CDiffSD/lib/python3.11/site-packages/accelerate/commands/accelerate_cli.py", line 46, in main
    args.func(args)
  File "/cluster/home/ckeusch/miniconda3/envs/CDiffSD/lib/python3.11/site-packages/accelerate/commands/launch.py", line 1066, in launch_command
    multi_gpu_launcher(args)
  File "/cluster/home/ckeusch/miniconda3/envs/CDiffSD/lib/python3.11/site-packages/accelerate/commands/launch.py", line 689, in multi_gpu_launcher
    current_env = prepare_multi_gpu_env(args)
                  ^^^^^^^^^^^^^^^^^^^^^^^^^^^
  File "/cluster/home/ckeusch/miniconda3/envs/CDiffSD/lib/python3.11/site-packages/accelerate/utils/launch.py", line 181, in prepare_multi_gpu_env
    raise ConnectionError(
ConnectionError: Tried to launch distributed communication on port `29500`, but another process is utilizing it. Please specify a different port (such as using the `--main_process_port` flag or specifying a different `main_process_port` in your config file) and rerun your script. To automatically use the next open port (on a single node), you can set this to `0`.
