The following values were not passed to `accelerate launch` and had defaults used instead:
	`--num_processes` was set to a value of `4`
	`--num_machines` was set to a value of `1`
	`--dynamo_backend` was set to a value of `'no'`
To avoid this warning pass in values for each of the problematic parameters or run `accelerate config`.
2024-12-10 23:18:42.787005: E external/local_xla/xla/stream_executor/cuda/cuda_fft.cc:477] Unable to register cuFFT factory: Attempting to register factory for plugin cuFFT when one has already been registered
2024-12-10 23:18:42.786995: E external/local_xla/xla/stream_executor/cuda/cuda_fft.cc:477] Unable to register cuFFT factory: Attempting to register factory for plugin cuFFT when one has already been registered
2024-12-10 23:18:42.786998: E external/local_xla/xla/stream_executor/cuda/cuda_fft.cc:477] Unable to register cuFFT factory: Attempting to register factory for plugin cuFFT when one has already been registered
2024-12-10 23:18:42.786995: E external/local_xla/xla/stream_executor/cuda/cuda_fft.cc:477] Unable to register cuFFT factory: Attempting to register factory for plugin cuFFT when one has already been registered
WARNING: All log messages before absl::InitializeLog() is called are written to STDERR
WARNING: All log messages before absl::InitializeLog() is called are written to STDERR
WARNING: All log messages before absl::InitializeLog() is called are written to STDERR
WARNING: All log messages before absl::InitializeLog() is called are written to STDERR
E0000 00:00:1733869122.906714   37812 cuda_dnn.cc:8310] Unable to register cuDNN factory: Attempting to register factory for plugin cuDNN when one has already been registered
E0000 00:00:1733869122.906711   37814 cuda_dnn.cc:8310] Unable to register cuDNN factory: Attempting to register factory for plugin cuDNN when one has already been registered
E0000 00:00:1733869122.906707   37813 cuda_dnn.cc:8310] Unable to register cuDNN factory: Attempting to register factory for plugin cuDNN when one has already been registered
E0000 00:00:1733869122.906704   37815 cuda_dnn.cc:8310] Unable to register cuDNN factory: Attempting to register factory for plugin cuDNN when one has already been registered
E0000 00:00:1733869122.943853   37812 cuda_blas.cc:1418] Unable to register cuBLAS factory: Attempting to register factory for plugin cuBLAS when one has already been registered
E0000 00:00:1733869122.943858   37814 cuda_blas.cc:1418] Unable to register cuBLAS factory: Attempting to register factory for plugin cuBLAS when one has already been registered
E0000 00:00:1733869122.943855   37813 cuda_blas.cc:1418] Unable to register cuBLAS factory: Attempting to register factory for plugin cuBLAS when one has already been registered
E0000 00:00:1733869122.943860   37815 cuda_blas.cc:1418] Unable to register cuBLAS factory: Attempting to register factory for plugin cuBLAS when one has already been registered
/cluster/home/ckeusch/miniconda3/envs/CDiffSD/lib/python3.11/site-packages/torch/nn/modules/conv.py:306: UserWarning: Applied workaround for CuDNN issue, install nvrtc.so (Triggered internally at /opt/conda/conda-bld/pytorch_1708025842427/work/aten/src/ATen/native/cudnn/Conv_v8.cpp:80.)
  return F.conv1d(input, weight, bias, self.stride,
/cluster/home/ckeusch/miniconda3/envs/CDiffSD/lib/python3.11/site-packages/torch/nn/modules/conv.py:306: UserWarning: Applied workaround for CuDNN issue, install nvrtc.so (Triggered internally at /opt/conda/conda-bld/pytorch_1708025842427/work/aten/src/ATen/native/cudnn/Conv_v8.cpp:80.)
  return F.conv1d(input, weight, bias, self.stride,
/cluster/home/ckeusch/miniconda3/envs/CDiffSD/lib/python3.11/site-packages/torch/nn/modules/conv.py:306: UserWarning: Applied workaround for CuDNN issue, install nvrtc.so (Triggered internally at /opt/conda/conda-bld/pytorch_1708025842427/work/aten/src/ATen/native/cudnn/Conv_v8.cpp:80.)
  return F.conv1d(input, weight, bias, self.stride,
/cluster/home/ckeusch/miniconda3/envs/CDiffSD/lib/python3.11/site-packages/torch/nn/modules/conv.py:306: UserWarning: Applied workaround for CuDNN issue, install nvrtc.so (Triggered internally at /opt/conda/conda-bld/pytorch_1708025842427/work/aten/src/ATen/native/cudnn/Conv_v8.cpp:80.)
  return F.conv1d(input, weight, bias, self.stride,
[rank1]:[E ProcessGroupNCCL.cpp:523] [Rank 1] Watchdog caught collective operation timeout: WorkNCCL(SeqNum=37396, OpType=ALLREDUCE, NumelIn=1, NumelOut=1, Timeout(ms)=600000) ran for 600351 milliseconds before timing out.
Error executing job with overrides: []
Traceback (most recent call last):
  File "/cluster/scratch/ckeusch/dsl-as24-challenge-3/src/main.py", line 54, in main
    model = train_model(cfg)
            ^^^^^^^^^^^^^^^^
  File "/cluster/scratch/ckeusch/dsl-as24-challenge-3/src/train.py", line 26, in train_model
    model = fit_clean_unet_pytorch(cfg)
            ^^^^^^^^^^^^^^^^^^^^^^^^^^^
  File "/cluster/scratch/ckeusch/dsl-as24-challenge-3/src/models/CleanUNet/train.py", line 379, in fit_clean_unet_pytorch
    train_model(
  File "/cluster/scratch/ckeusch/dsl-as24-challenge-3/src/models/CleanUNet/train.py", line 576, in train_model
    if val_c_loss:
       ^^^^^^^^^^
UnboundLocalError: cannot access local variable 'val_c_loss' where it is not associated with a value

Set the environment variable HYDRA_FULL_ERROR=1 for a complete stack trace.
[rank1]:[E ProcessGroupNCCL.cpp:537] Some NCCL operations have failed or timed out. Due to the asynchronous nature of CUDA kernels, subsequent GPU operations might run on corrupted/incomplete data.
[rank1]:[E ProcessGroupNCCL.cpp:543] To avoid data inconsistency, we are taking the entire process down.
[rank1]:[E ProcessGroupNCCL.cpp:1182] [Rank 1] NCCL watchdog thread terminated with exception: [Rank 1] Watchdog caught collective operation timeout: WorkNCCL(SeqNum=37396, OpType=ALLREDUCE, NumelIn=1, NumelOut=1, Timeout(ms)=600000) ran for 600351 milliseconds before timing out.
Exception raised from checkTimeout at /opt/conda/conda-bld/pytorch_1708025842427/work/torch/csrc/distributed/c10d/ProcessGroupNCCL.cpp:525 (most recent call first):
frame #0: c10::Error::Error(c10::SourceLocation, std::string) + 0x57 (0x150615b5cd87 in /cluster/home/ckeusch/miniconda3/envs/CDiffSD/lib/python3.11/site-packages/torch/lib/libc10.so)
frame #1: c10d::ProcessGroupNCCL::WorkNCCL::checkTimeout(std::optional<std::chrono::duration<long, std::ratio<1l, 1000l> > >) + 0x1e6 (0x1505b8952d26 in /cluster/home/ckeusch/miniconda3/envs/CDiffSD/lib/python3.11/site-packages/torch/lib/libtorch_cuda.so)
frame #2: c10d::ProcessGroupNCCL::workCleanupLoop() + 0x19d (0x1505b895627d in /cluster/home/ckeusch/miniconda3/envs/CDiffSD/lib/python3.11/site-packages/torch/lib/libtorch_cuda.so)
frame #3: c10d::ProcessGroupNCCL::ncclCommWatchdog() + 0x119 (0x1505b8956e79 in /cluster/home/ckeusch/miniconda3/envs/CDiffSD/lib/python3.11/site-packages/torch/lib/libtorch_cuda.so)
frame #4: <unknown function> + 0xd3e95 (0x150688842e95 in /cluster/home/ckeusch/miniconda3/envs/CDiffSD/bin/../lib/libstdc++.so.6)
frame #5: <unknown function> + 0x94ac3 (0x150689022ac3 in /lib/x86_64-linux-gnu/libc.so.6)
frame #6: <unknown function> + 0x126850 (0x1506890b4850 in /lib/x86_64-linux-gnu/libc.so.6)

terminate called after throwing an instance of 'c10::DistBackendError'
  what():  [Rank 1] NCCL watchdog thread terminated with exception: [Rank 1] Watchdog caught collective operation timeout: WorkNCCL(SeqNum=37396, OpType=ALLREDUCE, NumelIn=1, NumelOut=1, Timeout(ms)=600000) ran for 600351 milliseconds before timing out.
Exception raised from checkTimeout at /opt/conda/conda-bld/pytorch_1708025842427/work/torch/csrc/distributed/c10d/ProcessGroupNCCL.cpp:525 (most recent call first):
frame #0: c10::Error::Error(c10::SourceLocation, std::string) + 0x57 (0x150615b5cd87 in /cluster/home/ckeusch/miniconda3/envs/CDiffSD/lib/python3.11/site-packages/torch/lib/libc10.so)
frame #1: c10d::ProcessGroupNCCL::WorkNCCL::checkTimeout(std::optional<std::chrono::duration<long, std::ratio<1l, 1000l> > >) + 0x1e6 (0x1505b8952d26 in /cluster/home/ckeusch/miniconda3/envs/CDiffSD/lib/python3.11/site-packages/torch/lib/libtorch_cuda.so)
frame #2: c10d::ProcessGroupNCCL::workCleanupLoop() + 0x19d (0x1505b895627d in /cluster/home/ckeusch/miniconda3/envs/CDiffSD/lib/python3.11/site-packages/torch/lib/libtorch_cuda.so)
frame #3: c10d::ProcessGroupNCCL::ncclCommWatchdog() + 0x119 (0x1505b8956e79 in /cluster/home/ckeusch/miniconda3/envs/CDiffSD/lib/python3.11/site-packages/torch/lib/libtorch_cuda.so)
frame #4: <unknown function> + 0xd3e95 (0x150688842e95 in /cluster/home/ckeusch/miniconda3/envs/CDiffSD/bin/../lib/libstdc++.so.6)
frame #5: <unknown function> + 0x94ac3 (0x150689022ac3 in /lib/x86_64-linux-gnu/libc.so.6)
frame #6: <unknown function> + 0x126850 (0x1506890b4850 in /lib/x86_64-linux-gnu/libc.so.6)

Exception raised from ncclCommWatchdog at /opt/conda/conda-bld/pytorch_1708025842427/work/torch/csrc/distributed/c10d/ProcessGroupNCCL.cpp:1186 (most recent call first):
frame #0: c10::Error::Error(c10::SourceLocation, std::string) + 0x57 (0x150615b5cd87 in /cluster/home/ckeusch/miniconda3/envs/CDiffSD/lib/python3.11/site-packages/torch/lib/libc10.so)
frame #1: <unknown function> + 0xdef733 (0x1505b86ad733 in /cluster/home/ckeusch/miniconda3/envs/CDiffSD/lib/python3.11/site-packages/torch/lib/libtorch_cuda.so)
frame #2: <unknown function> + 0xd3e95 (0x150688842e95 in /cluster/home/ckeusch/miniconda3/envs/CDiffSD/bin/../lib/libstdc++.so.6)
frame #3: <unknown function> + 0x94ac3 (0x150689022ac3 in /lib/x86_64-linux-gnu/libc.so.6)
frame #4: <unknown function> + 0x126850 (0x1506890b4850 in /lib/x86_64-linux-gnu/libc.so.6)

[rank0]:[E ProcessGroupNCCL.cpp:523] [Rank 0] Watchdog caught collective operation timeout: WorkNCCL(SeqNum=37396, OpType=ALLREDUCE, NumelIn=350155, NumelOut=350155, Timeout(ms)=600000) ran for 600889 milliseconds before timing out.
[2024-12-11 00:32:00,975] torch.distributed.elastic.multiprocessing.api: [WARNING] Sending process 37812 closing signal SIGTERM
[2024-12-11 00:32:00,975] torch.distributed.elastic.multiprocessing.api: [WARNING] Sending process 37814 closing signal SIGTERM
[2024-12-11 00:32:00,976] torch.distributed.elastic.multiprocessing.api: [WARNING] Sending process 37815 closing signal SIGTERM
[2024-12-11 00:32:02,105] torch.distributed.elastic.multiprocessing.api: [ERROR] failed (exitcode: -6) local_rank: 1 (pid: 37813) of binary: /cluster/home/ckeusch/miniconda3/envs/CDiffSD/bin/python3.11
Traceback (most recent call last):
  File "/cluster/home/ckeusch/miniconda3/envs/CDiffSD/bin/accelerate", line 10, in <module>
    sys.exit(main())
             ^^^^^^
  File "/cluster/home/ckeusch/miniconda3/envs/CDiffSD/lib/python3.11/site-packages/accelerate/commands/accelerate_cli.py", line 46, in main
    args.func(args)
  File "/cluster/home/ckeusch/miniconda3/envs/CDiffSD/lib/python3.11/site-packages/accelerate/commands/launch.py", line 1066, in launch_command
    multi_gpu_launcher(args)
  File "/cluster/home/ckeusch/miniconda3/envs/CDiffSD/lib/python3.11/site-packages/accelerate/commands/launch.py", line 711, in multi_gpu_launcher
    distrib_run.run(args)
  File "/cluster/home/ckeusch/miniconda3/envs/CDiffSD/lib/python3.11/site-packages/torch/distributed/run.py", line 803, in run
    elastic_launch(
  File "/cluster/home/ckeusch/miniconda3/envs/CDiffSD/lib/python3.11/site-packages/torch/distributed/launcher/api.py", line 135, in __call__
    return launch_agent(self._config, self._entrypoint, list(args))
           ^^^^^^^^^^^^^^^^^^^^^^^^^^^^^^^^^^^^^^^^^^^^^^^^^^^^^^^^
  File "/cluster/home/ckeusch/miniconda3/envs/CDiffSD/lib/python3.11/site-packages/torch/distributed/launcher/api.py", line 268, in launch_agent
    raise ChildFailedError(
torch.distributed.elastic.multiprocessing.errors.ChildFailedError: 
======================================================
src/main.py FAILED
------------------------------------------------------
Failures:
  <NO_OTHER_FAILURES>
------------------------------------------------------
Root Cause (first observed failure):
[0]:
  time      : 2024-12-11_00:32:00
  host      : eu-g6-037.euler.ethz.ch
  rank      : 1 (local_rank: 1)
  exitcode  : -6 (pid: 37813)
  error_file: <N/A>
  traceback : Signal 6 (SIGABRT) received by PID 37813
======================================================
