The following values were not passed to `accelerate launch` and had defaults used instead:
	`--num_processes` was set to a value of `4`
	`--num_machines` was set to a value of `1`
	`--dynamo_backend` was set to a value of `'no'`
To avoid this warning pass in values for each of the problematic parameters or run `accelerate config`.
2024-12-09 10:19:38.809028: E external/local_xla/xla/stream_executor/cuda/cuda_fft.cc:477] Unable to register cuFFT factory: Attempting to register factory for plugin cuFFT when one has already been registered
2024-12-09 10:19:38.809028: E external/local_xla/xla/stream_executor/cuda/cuda_fft.cc:477] Unable to register cuFFT factory: Attempting to register factory for plugin cuFFT when one has already been registered
2024-12-09 10:19:38.809033: E external/local_xla/xla/stream_executor/cuda/cuda_fft.cc:477] Unable to register cuFFT factory: Attempting to register factory for plugin cuFFT when one has already been registered
2024-12-09 10:19:38.809028: E external/local_xla/xla/stream_executor/cuda/cuda_fft.cc:477] Unable to register cuFFT factory: Attempting to register factory for plugin cuFFT when one has already been registered
WARNING: All log messages before absl::InitializeLog() is called are written to STDERR
WARNING: All log messages before absl::InitializeLog() is called are written to STDERR
WARNING: All log messages before absl::InitializeLog() is called are written to STDERR
WARNING: All log messages before absl::InitializeLog() is called are written to STDERR
E0000 00:00:1733735978.827733 2511098 cuda_dnn.cc:8310] Unable to register cuDNN factory: Attempting to register factory for plugin cuDNN when one has already been registered
E0000 00:00:1733735978.827735 2511097 cuda_dnn.cc:8310] Unable to register cuDNN factory: Attempting to register factory for plugin cuDNN when one has already been registered
E0000 00:00:1733735978.827733 2511096 cuda_dnn.cc:8310] Unable to register cuDNN factory: Attempting to register factory for plugin cuDNN when one has already been registered
E0000 00:00:1733735978.827733 2511095 cuda_dnn.cc:8310] Unable to register cuDNN factory: Attempting to register factory for plugin cuDNN when one has already been registered
E0000 00:00:1733735978.833198 2511095 cuda_blas.cc:1418] Unable to register cuBLAS factory: Attempting to register factory for plugin cuBLAS when one has already been registered
E0000 00:00:1733735978.833198 2511098 cuda_blas.cc:1418] Unable to register cuBLAS factory: Attempting to register factory for plugin cuBLAS when one has already been registered
E0000 00:00:1733735978.833198 2511096 cuda_blas.cc:1418] Unable to register cuBLAS factory: Attempting to register factory for plugin cuBLAS when one has already been registered
E0000 00:00:1733735978.833199 2511097 cuda_blas.cc:1418] Unable to register cuBLAS factory: Attempting to register factory for plugin cuBLAS when one has already been registered
/cluster/home/ckeusch/miniconda3/envs/CDiffSD/lib/python3.11/site-packages/torch/nn/modules/conv.py:306: UserWarning: Applied workaround for CuDNN issue, install nvrtc.so (Triggered internally at /opt/conda/conda-bld/pytorch_1708025842427/work/aten/src/ATen/native/cudnn/Conv_v8.cpp:80.)
  return F.conv1d(input, weight, bias, self.stride,
/cluster/home/ckeusch/miniconda3/envs/CDiffSD/lib/python3.11/site-packages/torch/nn/modules/conv.py:306: UserWarning: Applied workaround for CuDNN issue, install nvrtc.so (Triggered internally at /opt/conda/conda-bld/pytorch_1708025842427/work/aten/src/ATen/native/cudnn/Conv_v8.cpp:80.)
  return F.conv1d(input, weight, bias, self.stride,
/cluster/home/ckeusch/miniconda3/envs/CDiffSD/lib/python3.11/site-packages/torch/nn/modules/conv.py:306: UserWarning: Applied workaround for CuDNN issue, install nvrtc.so (Triggered internally at /opt/conda/conda-bld/pytorch_1708025842427/work/aten/src/ATen/native/cudnn/Conv_v8.cpp:80.)
  return F.conv1d(input, weight, bias, self.stride,
/cluster/home/ckeusch/miniconda3/envs/CDiffSD/lib/python3.11/site-packages/torch/nn/modules/conv.py:306: UserWarning: Applied workaround for CuDNN issue, install nvrtc.so (Triggered internally at /opt/conda/conda-bld/pytorch_1708025842427/work/aten/src/ATen/native/cudnn/Conv_v8.cpp:80.)
  return F.conv1d(input, weight, bias, self.stride,
/cluster/home/ckeusch/miniconda3/envs/CDiffSD/lib/python3.11/site-packages/torch/functional.py:660: UserWarning: stft with return_complex=False is deprecated. In a future pytorch release, stft will return complex tensors for all inputs, and return_complex=False will raise an error.
Note: you can still call torch.view_as_real on the complex output to recover the old return format. (Triggered internally at /opt/conda/conda-bld/pytorch_1708025842427/work/aten/src/ATen/native/SpectralOps.cpp:874.)
  return _VF.stft(input, n_fft, hop_length, win_length, window,  # type: ignore[attr-defined]
/cluster/home/ckeusch/miniconda3/envs/CDiffSD/lib/python3.11/site-packages/torch/functional.py:660: UserWarning: stft with return_complex=False is deprecated. In a future pytorch release, stft will return complex tensors for all inputs, and return_complex=False will raise an error.
Note: you can still call torch.view_as_real on the complex output to recover the old return format. (Triggered internally at /opt/conda/conda-bld/pytorch_1708025842427/work/aten/src/ATen/native/SpectralOps.cpp:874.)
  return _VF.stft(input, n_fft, hop_length, win_length, window,  # type: ignore[attr-defined]
/cluster/home/ckeusch/miniconda3/envs/CDiffSD/lib/python3.11/site-packages/torch/functional.py:660: UserWarning: stft with return_complex=False is deprecated. In a future pytorch release, stft will return complex tensors for all inputs, and return_complex=False will raise an error.
Note: you can still call torch.view_as_real on the complex output to recover the old return format. (Triggered internally at /opt/conda/conda-bld/pytorch_1708025842427/work/aten/src/ATen/native/SpectralOps.cpp:874.)
  return _VF.stft(input, n_fft, hop_length, win_length, window,  # type: ignore[attr-defined]
/cluster/home/ckeusch/miniconda3/envs/CDiffSD/lib/python3.11/site-packages/torch/functional.py:660: UserWarning: stft with return_complex=False is deprecated. In a future pytorch release, stft will return complex tensors for all inputs, and return_complex=False will raise an error.
Note: you can still call torch.view_as_real on the complex output to recover the old return format. (Triggered internally at /opt/conda/conda-bld/pytorch_1708025842427/work/aten/src/ATen/native/SpectralOps.cpp:874.)
  return _VF.stft(input, n_fft, hop_length, win_length, window,  # type: ignore[attr-defined]
Error executing job with overrides: []
Error executing job with overrides: []
Error executing job with overrides: []
Traceback (most recent call last):
Traceback (most recent call last):
  File "/cluster/scratch/ckeusch/dsl-as24-challenge-3/src/main.py", line 56, in main
    model = train_model(cfg)
            ^^^^^^^^^^^^^^^^
  File "/cluster/scratch/ckeusch/dsl-as24-challenge-3/src/main.py", line 56, in main
    model = train_model(cfg)
            ^^^^^^^^^^^^^^^^
  File "/cluster/scratch/ckeusch/dsl-as24-challenge-3/src/train.py", line 25, in train_model
    model = fit_clean_unet_pytorch(cfg)
            ^^^^^^^^^^^^^^^^^^^^^^^^^^^
  File "/cluster/scratch/ckeusch/dsl-as24-challenge-3/src/train.py", line 25, in train_model
    model = fit_clean_unet_pytorch(cfg)
            ^^^^^^^^^^^^^^^^^^^^^^^^^^^
  File "/cluster/scratch/ckeusch/dsl-as24-challenge-3/src/models/CleanUNet/train.py", line 379, in fit_clean_unet_pytorch
    train_model(
  File "/cluster/scratch/ckeusch/dsl-as24-challenge-3/src/models/CleanUNet/train.py", line 379, in fit_clean_unet_pytorch
    train_model(
  File "/cluster/scratch/ckeusch/dsl-as24-challenge-3/src/models/CleanUNet/train.py", line 576, in train_model
    if val_c_loss:
       ^^^^^^^^^^
  File "/cluster/scratch/ckeusch/dsl-as24-challenge-3/src/models/CleanUNet/train.py", line 576, in train_model
    if val_c_loss:
       ^^^^^^^^^^
UnboundLocalError: cannot access local variable 'val_c_loss' where it is not associated with a value
UnboundLocalError: cannot access local variable 'val_c_loss' where it is not associated with a value
Traceback (most recent call last):

Set the environment variable HYDRA_FULL_ERROR=1 for a complete stack trace.

Set the environment variable HYDRA_FULL_ERROR=1 for a complete stack trace.
  File "/cluster/scratch/ckeusch/dsl-as24-challenge-3/src/main.py", line 56, in main
    model = train_model(cfg)
            ^^^^^^^^^^^^^^^^
  File "/cluster/scratch/ckeusch/dsl-as24-challenge-3/src/train.py", line 25, in train_model
    model = fit_clean_unet_pytorch(cfg)
            ^^^^^^^^^^^^^^^^^^^^^^^^^^^
  File "/cluster/scratch/ckeusch/dsl-as24-challenge-3/src/models/CleanUNet/train.py", line 379, in fit_clean_unet_pytorch
    train_model(
  File "/cluster/scratch/ckeusch/dsl-as24-challenge-3/src/models/CleanUNet/train.py", line 576, in train_model
    if val_c_loss:
       ^^^^^^^^^^
UnboundLocalError: cannot access local variable 'val_c_loss' where it is not associated with a value

Set the environment variable HYDRA_FULL_ERROR=1 for a complete stack trace.
Error executing job with overrides: []
Traceback (most recent call last):
  File "/cluster/scratch/ckeusch/dsl-as24-challenge-3/src/main.py", line 56, in main
    model = train_model(cfg)
            ^^^^^^^^^^^^^^^^
  File "/cluster/scratch/ckeusch/dsl-as24-challenge-3/src/train.py", line 25, in train_model
    model = fit_clean_unet_pytorch(cfg)
            ^^^^^^^^^^^^^^^^^^^^^^^^^^^
  File "/cluster/scratch/ckeusch/dsl-as24-challenge-3/src/models/CleanUNet/train.py", line 379, in fit_clean_unet_pytorch
    train_model(
  File "/cluster/scratch/ckeusch/dsl-as24-challenge-3/src/models/CleanUNet/train.py", line 576, in train_model
    if val_c_loss:
       ^^^^^^^^^^
UnboundLocalError: cannot access local variable 'val_c_loss' where it is not associated with a value

Set the environment variable HYDRA_FULL_ERROR=1 for a complete stack trace.
[2024-12-09 10:22:22,801] torch.distributed.elastic.multiprocessing.api: [ERROR] failed (exitcode: 1) local_rank: 0 (pid: 2511095) of binary: /cluster/home/ckeusch/miniconda3/envs/CDiffSD/bin/python3.11
Traceback (most recent call last):
  File "/cluster/home/ckeusch/miniconda3/envs/CDiffSD/bin/accelerate", line 10, in <module>
    sys.exit(main())
             ^^^^^^
  File "/cluster/home/ckeusch/miniconda3/envs/CDiffSD/lib/python3.11/site-packages/accelerate/commands/accelerate_cli.py", line 46, in main
    args.func(args)
  File "/cluster/home/ckeusch/miniconda3/envs/CDiffSD/lib/python3.11/site-packages/accelerate/commands/launch.py", line 1066, in launch_command
    multi_gpu_launcher(args)
  File "/cluster/home/ckeusch/miniconda3/envs/CDiffSD/lib/python3.11/site-packages/accelerate/commands/launch.py", line 711, in multi_gpu_launcher
    distrib_run.run(args)
  File "/cluster/home/ckeusch/miniconda3/envs/CDiffSD/lib/python3.11/site-packages/torch/distributed/run.py", line 803, in run
    elastic_launch(
  File "/cluster/home/ckeusch/miniconda3/envs/CDiffSD/lib/python3.11/site-packages/torch/distributed/launcher/api.py", line 135, in __call__
    return launch_agent(self._config, self._entrypoint, list(args))
           ^^^^^^^^^^^^^^^^^^^^^^^^^^^^^^^^^^^^^^^^^^^^^^^^^^^^^^^^
  File "/cluster/home/ckeusch/miniconda3/envs/CDiffSD/lib/python3.11/site-packages/torch/distributed/launcher/api.py", line 268, in launch_agent
    raise ChildFailedError(
torch.distributed.elastic.multiprocessing.errors.ChildFailedError: 
============================================================
src/main.py FAILED
------------------------------------------------------------
Failures:
[1]:
  time      : 2024-12-09_10:22:22
  host      : eu-g3-052.euler.ethz.ch
  rank      : 1 (local_rank: 1)
  exitcode  : 1 (pid: 2511096)
  error_file: <N/A>
  traceback : To enable traceback see: https://pytorch.org/docs/stable/elastic/errors.html
[2]:
  time      : 2024-12-09_10:22:22
  host      : eu-g3-052.euler.ethz.ch
  rank      : 2 (local_rank: 2)
  exitcode  : 1 (pid: 2511097)
  error_file: <N/A>
  traceback : To enable traceback see: https://pytorch.org/docs/stable/elastic/errors.html
[3]:
  time      : 2024-12-09_10:22:22
  host      : eu-g3-052.euler.ethz.ch
  rank      : 3 (local_rank: 3)
  exitcode  : 1 (pid: 2511098)
  error_file: <N/A>
  traceback : To enable traceback see: https://pytorch.org/docs/stable/elastic/errors.html
------------------------------------------------------------
Root Cause (first observed failure):
[0]:
  time      : 2024-12-09_10:22:22
  host      : eu-g3-052.euler.ethz.ch
  rank      : 0 (local_rank: 0)
  exitcode  : 1 (pid: 2511095)
  error_file: <N/A>
  traceback : To enable traceback see: https://pytorch.org/docs/stable/elastic/errors.html
============================================================
